<?xml version="1.0"?>
<robot name="explorer_ds1">

  <link name="base_footprint"/> <joint name="base_footprint_to_base_link_joint" type="fixed">
    <parent link="base_footprint"/>
    <child link="base_link"/>
    <origin xyz="0 0 0" rpy="0 0 0"/>
  </joint>

  <link name="base_link">
    <inertial>
      <mass value="1.55"/>
      <origin xyz="0 0 0" rpy="0 0 0"/> <inertia ixx="0.025" ixy="0" ixz="0" iyy="0.009" iyz="0" izz="0.033"/>
    </inertial>
    <visual name="base_link_visual">
      <origin xyz="0 0 0" rpy="0 0 0"/>
      <geometry>
        <mesh filename="package://ros_gz_example_description/models/explorer_ds1/meshes/DS1.dae"/>
      </geometry>
      <material name="grey">
        <color rgba="0.7 0.7 0.7 1"/>
      </material>
    </visual>
    <collision name="base_link_collision">
      <origin xyz="0 0 0.019" rpy="0 0 0"/>
      <geometry>
        <mesh filename="package://ros_gz_example_description/models/explorer_ds1/meshes/DS1_COLLISION.STL"/>
      </geometry>
    </collision>

    <visual name="rs_front_visual_on_base">
      <origin xyz="0.3 0 0.07" rpy="0 0 1.57079632679"/>
      <geometry>
        <mesh filename="package://ros_gz_example_description/models/explorer_ds1/meshes/realsense.dae"/>
      </geometry>
      <material name="realsense_material"/>
    </visual>

    <visual name="front_left_led_visual">
      <origin xyz="0.39 -0.166 0.065" rpy="0 1.57079632679 0"/>
      <geometry>
        <mesh filename="package://ros_gz_example_description/models/explorer_ds1/meshes/led.dae" scale="0.5 0.5 0.5"/>
      </geometry>
      <material name="led_material">
        <color rgba="0.8 0.1 0.1 1"/>
      </material>
    </visual>
    <visual name="front_right_led_visual">
      <origin xyz="0.39 0.166 0.065" rpy="0 1.57079632679 0"/>
      <geometry>
        <mesh filename="package://ros_gz_example_description/models/explorer_ds1/meshes/led.dae" scale="0.5 0.5 0.5"/>
      </geometry>
      <material name="led_material"/>
    </visual>
    <visual name="up_left_led_visual">
      <origin xyz="0.36 -0.166 0.07" rpy="0 0 0"/>
      <geometry>
        <mesh filename="package://ros_gz_example_description/models/explorer_ds1/meshes/led.dae" scale="0.5 0.5 0.5"/>
      </geometry>
      <material name="led_material"/>
    </visual>
    <visual name="up_right_led_visual">
      <origin xyz="0.36 0.166 0.07" rpy="0 0 0"/>
      <geometry>
        <mesh filename="package://ros_gz_example_description/models/explorer_ds1/meshes/led.dae" scale="0.5 0.5 0.5"/>
      </geometry>
      <material name="led_material"/>
    </visual>
    <visual name="down_left_led_visual">
      <origin xyz="0.36 -0.166 0.06" rpy="0 -3.14159265359 0"/>
      <geometry>
        <mesh filename="package://ros_gz_example_description/models/explorer_ds1/meshes/led.dae" scale="0.5 0.5 0.5"/>
      </geometry>
      <material name="led_material"/>
    </visual>
    <visual name="down_right_led_visual">
      <origin xyz="0.36 0.166 0.06" rpy="0 -3.14159265359 0"/>
      <geometry>
        <mesh filename="package://ros_gz_example_description/models/explorer_ds1/meshes/led.dae" scale="0.5 0.5 0.5"/>
      </geometry>
      <material name="led_material"/>
    </visual>

    <visual name="laser_visual_base1_on_base">
      <origin xyz="0.18 0 0.19" rpy="0 0 0"/>
      <geometry>
        <mesh filename="package://ros_gz_example_description/models/explorer_ds1/meshes/VLP16_base_1.dae"/>
      </geometry>
      <material name="lidar_material">
        <color rgba="0.2 0.2 0.2 1"/>
      </material>
    </visual>
    <visual name="laser_visual_base2_on_base">
      <origin xyz="0.18 0 0.19" rpy="0 0 0"/>
      <geometry>
        <mesh filename="package://ros_gz_example_description/models/explorer_ds1/meshes/VLP16_base_2.dae"/>
      </geometry>
      <material name="lidar_material"/>
    </visual>
    <visual name="laser_visual_scan_on_base">
      <origin xyz="0.18 0 0.19" rpy="0 0 0"/>
      <geometry>
        <mesh filename="package://ros_gz_example_description/models/explorer_ds1/meshes/VLP16_scan.dae"/>
      </geometry>
      <material name="lidar_material"/>
    </visual>
  </link>

  <link name="imu_sensor"/>
  <joint name="imu_joint" type="fixed">
    <parent link="base_link"/>
    <child link="imu_sensor"/>
    <origin xyz="0 0 0" rpy="0 0 0"/> </joint>

  <link name="magnetometer_link"/>
  <joint name="magnetometer_joint" type="fixed">
    <parent link="base_link"/>
    <child link="magnetometer_link"/>
    <origin xyz="0 0 0" rpy="0 0 0"/> </joint>


  <link name="rs_front"/>
  <joint name="rs_front_camera_joint" type="fixed">
    <parent link="base_link"/>
    <child link="rs_front"/>
    <origin xyz="0.325 0 0.07" rpy="0 0 0"/>
  </joint>
  <link name="rs_front_camera_color_optical_frame" />
  <joint name="rs_front_camera_color_optical_joint" type="fixed">
      <origin xyz="0 0 0" rpy="-1.57079632679 0 -1.57079632679"/>
      <parent link="rs_front"/>
      <child link="rs_front_camera_color_optical_frame"/>
  </joint>


  <link name="front_laser"/>
  <joint name="front_laser_joint" type="fixed">
    <parent link="base_link"/>
    <child link="front_laser"/>
    <origin xyz="0.18 0 0.284" rpy="0 0 0"/>
  </joint>

  <link name="rotor_0">
    <inertial>
      <mass value="0.005"/>
      <origin xyz="0 0 0" rpy="0 0 0"/>
      <inertia ixx="9.75e-07" ixy="0" ixz="0" iyy="4.17041e-05" iyz="0" izz="4.26041e-05"/>
    </inertial>
    <visual name="rotor_0_visual">
      <origin xyz="0 0 0" rpy="0 0 0"/>
      <geometry>
        <mesh filename="package://ros_gz_example_description/models/explorer_ds1/meshes/propeller_ccw.dae" scale="0.12 0.12 0.12"/>
      </geometry>
      <material name="black">
        <color rgba="0.1 0.1 0.1 1"/>
      </material>
    </visual>
    </link>
  <joint name="rotor_0_joint" type="revolute">
    <parent link="base_link"/>
    <child link="rotor_0"/>
    <origin xyz="0.1644 -0.166 0.023" rpy="0 0 0"/>
    <axis xyz="0 0 1"/>
    <limit lower="-1e16" upper="1e16" effort="800" velocity="800"/> <dynamics damping="0.0" friction="0.0"/>
  </joint>

  <link name="rotor_1">
    <inertial>
      <mass value="0.005"/>
      <origin xyz="0 0 0" rpy="0 0 0"/>
      <inertia ixx="9.75e-07" ixy="0" ixz="0" iyy="4.17041e-05" iyz="0" izz="4.26041e-05"/>
    </inertial>
    <visual name="rotor_1_visual">
      <origin xyz="0 0 0" rpy="0 0 0"/>
      <geometry>
        <mesh filename="package://ros_gz_example_description/models/explorer_ds1/meshes/propeller_ccw.dae" scale="0.12 0.12 0.12"/>
      </geometry>
      <material name="black"/>
    </visual>
  </link>
  <joint name="rotor_1_joint" type="revolute">
    <parent link="base_link"/>
    <child link="rotor_1"/>
    <origin xyz="-0.16443 0.1661 0.023" rpy="0 0 0"/>
    <axis xyz="0 0 1"/>
    <limit lower="-1e16" upper="1e16" effort="800" velocity="800"/>
    <dynamics damping="0.0" friction="0.0"/>
  </joint>

  <link name="rotor_2">
    <inertial>
      <mass value="0.005"/>
      <origin xyz="0 0 0" rpy="0 0 0"/>
      <inertia ixx="9.75e-07" ixy="0" ixz="0" iyy="4.17041e-05" iyz="0" izz="4.26041e-05"/>
    </inertial>
    <visual name="rotor_2_visual">
      <origin xyz="0 0 0" rpy="0 0 0"/>
      <geometry>
        <mesh filename="package://ros_gz_example_description/models/explorer_ds1/meshes/propeller_cw.dae" scale="0.12 0.12 0.12"/>
      </geometry>
      <material name="black"/>
    </visual>
  </link>
  <joint name="rotor_2_joint" type="revolute">
    <parent link="base_link"/>
    <child link="rotor_2"/>
    <origin xyz="0.16443 0.1661 0.023" rpy="0 0 0"/>
    <axis xyz="0 0 1"/>
    <limit lower="-1e16" upper="1e16" effort="800" velocity="800"/>
    <dynamics damping="0.0" friction="0.0"/>
  </joint>

  <link name="rotor_3">
    <inertial>
      <mass value="0.005"/>
      <origin xyz="0 0 0" rpy="0 0 0"/>
      <inertia ixx="9.75e-07" ixy="0" ixz="0" iyy="4.17041e-05" iyz="0" izz="4.26041e-05"/>
    </inertial>
    <visual name="rotor_3_visual">
      <origin xyz="0 0 0" rpy="0 0 0"/>
      <geometry>
        <mesh filename="package://ros_gz_example_description/models/explorer_ds1/meshes/propeller_cw.dae" scale="0.12 0.12 0.12"/>
      </geometry>
      <material name="black"/>
    </visual>
  </link>
  <joint name="rotor_3_joint" type="revolute">
    <parent link="base_link"/>
    <child link="rotor_3"/>
    <origin xyz="-0.16443 -0.1661 0.023" rpy="0 0 0"/>
    <axis xyz="0 0 1"/>
    <limit lower="-1e16" upper="1e16" effort="800" velocity="800"/>
    <dynamics damping="0.0" friction="0.0"/>
  </joint>

  <material name="realsense_material"> <color rgba="0.5 0.5 0.6 1"/>
  </material>
  <material name="led_material"> <color rgba="0.8 0.1 0.1 1"/>
  </material>
   <material name="lidar_material"> <color rgba="0.2 0.2 0.2 1"/>
   </material>

</robot>